# 前言

常考的代码输出题主要涉及以下知识点：异步编程、事件循环、this指向、作用域、变量提升、闭包、原型、继承等。

# 一、异步&事件循环

## 题1：promise

```javascript
const promise = new Promise((resolve,reject)=>{
    console.log(1);
    console.log(2);
})
promise.then(()=>{
    console.log(3);
});
console.log(4);
```

输出结果：

```javascript
1
2
4
```

> promise.then是微任务，它会在所有的宏任务执行完之后才会执行，同时需要promise内部的状态发生变化，因为这里内部没有发生变化，一直处于pending状态，所以不输出3。

## 题2：promise	

```javascript
const promise1 = new Promise((resolve,reject)=>{
    console.log('promise1');
    resolve('resolve1');
})
const promise2 = promise1.then(res=>{
    console.log(res);
})
console.log('1',promise1);
console.log('2',promise2);
```

输出结果：

```javascript
promise1
1 Promise{<resolved>:resolve1}
2 Promise{<pending>}
resolve1
```

**需要注意的是，直接打印promise1，会打印出它的状态值和参数。**

代码执行过程如下：

1. script是一个宏任务，按照顺序执行这些代码；
2. 首先进入Promise，执行该构造函数中的代码，打印`promise1`；
3. 碰到`resolve`函数, 将`promise1`的状态改变为`resolved`, 并将结果保存下来；
4. 碰到`promise1.then`这个微任务，将它放入微任务队列；
5. `promise2`是一个新的状态为`pending`的`Promise`；
6. 执行同步代码1， 同时打印出`promise1`的状态是`resolved`；
7. 执行同步代码2，同时打印出`promise2`的状态是`pending`；
8. 宏任务执行完毕，查找微任务队列，发现`promise1.then`这个微任务且状态为`resolved`，执行它。

## 题3

```javascript
const promise = new Promise((resolve, reject) => {
  console.log(1);
  setTimeout(() => {
    console.log("timerStart");
    resolve("success");
    console.log("timerEnd");
  }, 0);
  console.log(2);
});
promise.then((res) => {
  console.log(res);
});
console.log(4);
```

输出结果：

```javascript
1
2
4
timerStart
timerEnd
success
```

代码执行过程如下：

1. 首先遇到Promise构造函数，会先执行里面的内容，打印`1`；
2. 遇到定时器`steTimeout`，它是一个宏任务，放入宏任务队列；
3. 继续向下执行，打印出2；
4. 由于`Promise`的状态此时还是`pending`，所以`promise.then`先不执行；
5. 继续执行下面的同步任务，打印出4；
6. 此时微任务队列没有任务，继续执行下一轮宏任务，执行`steTimeout`；
7. 首先执行`timerStart`，然后遇到了`resolve`，将`promise`的状态改为`resolved`且保存结果并将之前的`promise.then`推入微任务队列，再执行`timerEnd`；
8. 执行完这个宏任务，就去执行微任务`promise.then`，打印出`resolve`的结果。

## 题4：宏微队列

```javascript
Promise.resolve().then(() => {
  console.log('promise1');
  const timer2 = setTimeout(() => {
    console.log('timer2')
  }, 0)
});
const timer1 = setTimeout(() => {
  console.log('timer1')
  Promise.resolve().then(() => {
    console.log('promise2')
  })
}, 0)
console.log('start');
```

输出结果：

```javascript
start
promise1
timer1
promise2
timer2
```

代码执行过程：

1. 首先，`promise.resolve().then（这里记为PA）`是一个微任务，加入微任务队列
2. 执行timer1，它是一个宏任务，加入宏任务队列
3. 继续执行下面的同步代码，打印出 `start`
4. 这样第一轮宏任务就执行完了，开始执行微任务 `PA`，打印出 `promise1`
5. 遇到 `timer2`，这是一个宏任务，将其加入宏任务队列，此时宏任务队列有两个任务，分别是 `timer1`、`timer2`
6. 这样第一轮微任务就完成了，开始执行第二轮宏任务，首先执行定时器 timer1，打印 timer1；
7. 遇到 `Promise.resolve().then（即为PB）`，是一个微任务， 加入微任务队列
8. 开始执行微任务PB，打印 `promise2`
9. 最后执行宏任务 timer2 定时器，打印出 timer2

## 题5：promise状态

```javascript
const promise = new Promise((resolve, reject) => {
    resolve('success1');
    reject('error');
    resolve('success2');
});
promise.then((res) => {
    console.log('then:', res);
}).catch((err) => {
    console.log('catch:', err);
})
```

输出结果：

```javascript
then: success1
```

**Promise在状态发生变化之后，就不会再发生改变。只能改变状态一次**。此时状态已经变为完成状态，即catch不会捕获到错误。

## 题6：promise.resolve

```javascript
Promise.resolve(1)
  .then(2)
  .then(Promise.resolve(3))
  .then(console.log)
```

输出结果：

```javascript
1
//此时的Promise状态：Promise{<fulfilled>:undefined}
```

> `Promsie.resolve`方法的参数如果是一个原始值，或者是一个不具有then方法的对象，则Promise.resolve方法返回一个新的Promise对象，状态为resolved，Promise.resolve方法的参数，会同时传递给回调函数。
>
> then方法接受的参数是函数，而如果传递的并非是一个函数，它实际上会将其解释为then（null），这就会导致前一个Promise的结果会传递到下面。

## 题7

```javascript
const promise1 = new Promise((resolve, reject) => {
  setTimeout(() => {
    resolve('success')
  }, 1000)
})
const promise2 = promise1.then(() => {
  throw new Error('error!!!')
})
console.log('promise1', promise1)
console.log('promise2', promise2)
setTimeout(() => {
  console.log('promise1', promise1)
  console.log('promise2', promise2)
}, 2000)
```

输出结果：

```javascript
promise1 Promise{<pending>}
promise2 Promise{<pending>}

Uncaught (in promise) Error: error!!!
promise1 Promise {<fulfilled>:"success"}
promise2 Promise {<rejected}: Error:error!!!}
```

> then的执行不一定要等待状态改变后才执行。

## 题8：promise的链式调用（关于catch）

```javascript
Promise.resolve(1)
  .then(res => {
    console.log(res);
    return 2;
  })
  .catch(err => {
    return 3;
  })
  .then(res => {
    console.log(res);
  });
```

输出结果：

```javascript
1
2
```

> Promise是可以链式调用的，由于每次调用 `.then`或者 `.catch`都会返回一个**新的promise**，从而实现了链式调用，它并不像一般任务的链式调用一样 `return this`。
>
> - **Promise.prototype.catch()方法是.then(null, rejection)或.then(undefined, rejection)的别名，用于指定发生错误时的回调函数。**

上面的输出结果之后之所以依次打印出1和2，是因为 `resolve(1)`之后走的是第一个then方法，并没有进入catch里，所以第二个then中的`res`得到的实际上是第一个then的返回值。并且`return 2`会被包装成 `resolve(2)`，被最后的then打印输出2。

## 题9：promise的返回值

```javascript
Promise.resolve().then(() => {
  return new Error('error!!!')
}).then(res => {
  console.log("then: ", res)
}).catch(err => {
  console.log("catch: ", err)
})
```

输出结果：

```javascript
then: Error : error!!!
```

> 返回任意一个**非Promise**的值都会被包裹成promise对象，因此这里的 `return new Error('error!!!')`也被包裹成了 `return Promise.resolve(new Error('error!!!'))`，因此它会被then捕获而不是catch。

## 题10：返回值不能是promise本身

```javascript
const promise = Promise.resolve().then(() => {
  return promise;
})
promise.catch(console.err)
```

输出结果：

```javascript
Uncaught (in promise) TypeError: Chaining cycle detected for promise #<Promise>
```

这里其实是一个坑，`.then`或 `.catch`返回的值不能是 promise本身，否则会造成死循环。

## 题11 then值透传

```javascript
Promise.resolve(1)
  .then(2)
  .then(Promise.resolve(3))
  .then(console.log)
```

输出结果：

```javascript
1
```

> **只需记住一个原则**：**`.then`或 `.catch`的期望参数是函数，传入非函数会发生值透传**。

第一个then和第二then中传入的都不是函数，一个是数字，一个是对象，因此发生了透传，将 `resolve(1)`的值直接传到最后一个then里，直接打印出1。

## 题12 promise失败的处理

```javascript
Promise.reject('err!!!')
  .then((res) => {
    console.log('success', res)
  }, (err) => {
    console.log('error', err)
  }).catch(err => {
    console.log('catch', err)
  })
```

输出结果：

```javascript
error err!!!
```

我们知道，`.then`函数中的两个参数：

- 第一个参数是用来处理Promise成功的函数
- 第二个则是处理失败的函数

也就是说`Promise.resolve('1')`的值会进入成功的函数，`Promise.reject('2')`的值会进入失败的函数。

在这道题中，错误直接被`then`的第二个参数捕获了，所以就不会被`catch`捕获了，输出结果为：`error err!!!'`

但是，如果是像下面这样：

```javascript
Promise.resolve()
  .then(function success (res) {
    throw new Error('error!!!')
  }, function fail1 (err) {
    console.log('fail1', err)
  }).catch(function fail2 (err) {
    console.log('fail2', err)
  })
```

在`then`的第一参数中抛出了错误，那么他就不会被第二个参数不活了，而是被后面的`catch`捕获到。

## 题13 promsie的finally

```javascript
Promise.resolve('1')
  .then(res => {
    console.log(res)
  })
  .finally(() => {
    console.log('finally')
  })
Promise.resolve('2')
  .finally(() => {
    console.log('finally2')
  	return '我是finally2返回的值'
  })
  .then(res => {
    console.log('finally2后面的then函数', res)
  })
```

结果输出：

```javascript
1
finally2
finally
finally2后面的then函数 2
```

`finally()`一般用的很少，只要记住以下几点就可以了：

- `finally()`不管Promise对象最后的状态如何都会执行
- `.finally()`方法的回调函数不接受任何的参数，也就是说你在 `.finally()`函数中是无法知道Promise最终的状态是 resolved 还是 rejected的
- 它最终返回的默认会是一个上一次的Promise对象值，不过如果抛出的是一个异常则返回异常的Promise对象。
- finally本质上是then方法的特例

**.finally()的错误捕获**：

```javascript
Promise.resolve('1')
  .finally(() => {
    console.log('finally1')
    throw new Error('我是finally中抛出的异常')
  })
  .then(res => {
    console.log('finally后面的then函数', res)
  })
  .catch(err => {
    console.log('捕获错误', err)
  })
```

输出结果：

```javascript
finally1
捕获错误 Error: 我是finally中抛出的异常
```

## 题14 promise.all

```javascript
function runAsync (x) {
    const p = new Promise(r => setTimeout(() => r(x, console.log(x)), 1000))
    return p
}

Promise.all([runAsync(1), runAsync(2), runAsync(3)]).then(res => console.log(res))
```

输出结果：

```javascript
1
2
3
[1,2,3]
```

首先，定义了一个Promise，来异步执行函数runAsync，该函数传入一个值x，然后间隔一秒后打印出这个x。

之后再使用 `Promise.all`来执行这个函数，执行的时候，看到一秒之后输出了1,2,3.同时输出了数组 [1,2,3]，三个函数是同步执行的，并且在一个回调函数中返回了所有的结果。并且结果和函数的执行顺序是一致的。

## 题15 all和catch

```javascript
function runAsync (x) {
  const p = new Promise(r => setTimeout(() => r(x, console.log(x)), 1000))
  return p
}
function runReject (x) {
  const p = new Promise((res, rej) => setTimeout(() => rej(`Error: ${x}`, console.log(x)), 1000 * x))
  return p
}
Promise.all([runAsync(1), runReject(4), runAsync(3), runReject(2)])
       .then(res => console.log(res))
       .catch(err => console.log(err))
```

输出结果：

```javascript
// 1s后输出
1
3
// 2s后输出
2
Error: 2
// 4s后输出
4
```

为什么不会输出 `Error:4` ？因为catch只能捕获第一次错误。在这里最先的错误就是 `runReject(2)`的结果。如果一组异步操作中有一个异常都不会进入 `.then()`的第一个回调函数参数中。会被 `.then()`的第二个回调函数捕获。

## 题16 promise.race

```javascript
function runAsync (x) {
  const p = new Promise(r => setTimeout(() => r(x, console.log(x)), 1000))
  return p
}
Promise.race([runAsync(1), runAsync(2), runAsync(3)])
  .then(res => console.log('result: ', res))
  .catch(err => console.log(err))
```

输出结果：

```javascript
1
result: 1
2
3
```

`race`是捕获执行结果出的最快的那个方法，只捕获一个。**其他**函数虽然**还会继续执行**，但是 不是被then捕获了。

## 题17 race

```javascript
function runAsync(x) {
  const p = new Promise(r =>
    setTimeout(() => r(x, console.log(x)), 1000)
  );
  return p;
}
function runReject(x) {
  const p = new Promise((res, rej) =>
    setTimeout(() => rej(`Error: ${x}`, console.log(x)), 1000 * x)
  );
  return p;
}
Promise.race([runReject(0), runAsync(1), runAsync(2), runAsync(3)])
  .then(res => console.log("result: ", res))
  .catch(err => console.log(err));
```

输出结果：

```javascript
0
Error: 0
1
2
3
```

可以看到在catch捕获到第一个错误之后，后面的代码还会执行，不过不会再被捕获了。

注意：`all`和 `race`传入的数组中如果有会抛出异常的异步任务，那么只有最先抛出的错误会被捕获，并且是被then的第二个参数或者后面的catch捕获；**但并不会影响数组中其他的异步任务的执行**。

## 题18 async经典初级

```javascript
async function async1() {
  console.log("async1 start");
  await async2();
  console.log("async1 end");
}
async function async2() {
  console.log("async2");
}
async1();
console.log('start')
```

输出结果：

```javascript
async1 start
async2
start 
async1 end
```

代码的执行过程：

1. 首先执行函数中的同步代码 `async1 start`，之后遇到了 `await`，它会阻塞 `async1`后面代码的执行，因此会先去执行 `async2`中的同步代码 `async2`，然后跳出`async1`
2. 跳出 `async1`函数后，执行同步代码 `start`
3. 在一轮宏任务全部执行完毕之后，再来执行 `await`后面的内容 `async1 end`

> 这里可以理解为await后面的语句相当于放到了new Promise中，下一行及之后的语句相当于放在Promise.then中。

## 题19 async 和 setTimeOut

```javascript
async function async1() {
  console.log("async1 start");
  await async2();
  console.log("async1 end");
  setTimeout(() => {
    console.log('timer1')
  }, 0)
}
async function async2() {
  setTimeout(() => {
    console.log('timer2')
  }, 0)
  console.log("async2");
}
async1();
setTimeout(() => {
  console.log('timer3')
}, 0)
console.log("start")
```

输出结果：

```javascript
async1 start    //我的结果：
async2
start
async1 end
timer2          //timer3
timer3          //timer2
timer1
```

代码的执行过程如下：

1. 首先进入`async1`，打印出`async1 start`；
2. 之后遇到`async2`，进入`async2`，遇到定时器`timer2`，加入宏任务队列，之后打印`async2`；
3. 由于`async2`阻塞了后面代码的执行，所以执行后面的定时器`timer3`，将其加入宏任务队列，之后打印`start`；
4. 然后执行async2后面的代码，打印出`async1 end`，遇到定时器timer1，将其加入宏任务队列；
5. 最后，宏任务队列有三个任务，先后顺序为`timer2`，`timer3`，`timer1`，没有微任务，所以直接所有的宏任务按照先进先出的原则执行。

## 题20 async & promise

```javascript
async function async1 () {
  console.log('async1 start');
  await new Promise(resolve => {
    console.log('promise1')
  })
  console.log('async1 success');
  return 'async1 end'
}
console.log('srcipt start')
async1().then(res => console.log(res))
console.log('srcipt end')
```

输出结果：

```javascript
srcipt start
async1 start
promise1
srcipt end
```

> 这里要注意 `async1`中 `await`后面的Promise是没有返回值的，也就是它的状态始终是 `pending`状态，所以在 `await`之后的内容是不会执行的，包括 `async1`后面的 `.then`。
>
> **给自己**：注意，上面`async1().then()`中 `async1()`就是调用了。

## 题21 async & promsie

上一题的改进，加上了 resolve

```javascript
async function async1 () {
  console.log('async1 start');
  await new Promise(resolve => {
    console.log('promise1')
    resolve('promise1 resolve')
  }).then(res => console.log(res))
  console.log('async1 success');
  return 'async1 end'
}
console.log('srcipt start')
async1().then(res => console.log(res))
console.log('srcipt end')
```

输出结果：

```javascript
srcipt start
async1 start
promise1
srcipt end
promise1 resolve
async1 success
async1 end
```

> 反正就是记住有什么任务就进什么队列。

## 题22 async & promise & setTimeOut

```javascript
async function async1() {
  console.log("async1 start");
  await async2();
  console.log("async1 end");
}

async function async2() {
  console.log("async2");
}

console.log("script start");

setTimeout(function() {
  console.log("setTimeout");
}, 0);

async1();

new Promise(resolve => {
  console.log("promise1");
  resolve();
}).then(function() {
  console.log("promise2");
});
console.log('script end')
```

输出结果：

```javascript
script start
async1 start
async2
promise1
script end
async1 end
promise2
setTimeout
```

代码执行过程如下：

1. 开头定义了 async1 和 async2两个函数，但是并未执行，执行script中的代码，所以打印出 script start；
2. 遇到定时器setTimeOut，加入宏任务队列
3. 之后执行函数async1 ，首先打印出 async1 start
4. 遇到await，执行async2；打印出async2，并阻断后面代码的执行，将后面的代码加入到微任务队列；
5. 然后跳出async1 和 async2，遇到Promise，打印出promise1；
6. 遇到resolve，将其加入到微任务队列，然后执行后面的script代码，打印出script end；
7. 之后就该执行微任务队列了，首先打印出 async1 end，然后打印出 promise2；
8. 执行完微任务队列，就开始执行宏任务队列中的定时器，打印出setTimeOut。

## 题23 async & promsie.reject

```javascript
async function async1 () {
  await async2();
  console.log('async1');
  return 'async1 success'
}
async function async2 () {
  return new Promise((resolve, reject) => {
    console.log('async2')
    reject('error')
  })
}
async1().then(res => console.log(res))
```

输出结果：

```javascript
async2
Uncaught (in promise) error
```

> 可以看到，如果async函数中抛出了错误，就会终止错误结果，不会继续向下执行。

如果想要让错误不足之处后面的代码执行，可以使用catch来捕获：

```javascript
async function async1 () {
  await Promise.reject('error!!!').catch(e => console.log(e))
  console.log('async1');
  return Promise.resolve('async1 success')
}
async1().then(res => console.log(res))
console.log('script start')
```

输出结果：

```javascript
script start
error!!!
async1
async1 success
```

![image-20220320171452098](https://gitee.com/guoluyan53/image-bed/raw/master/img/image-20220320171452098.png)



